Workbook

Sheet Contents
B2: October 2026 Economic and fiscal outlook – detailed forecast tables: economy
B3: Table 1.1: GDP Expenditure Components (Chain-Linked Volumes)
B4: Table 1.2: GDP Expenditure Components (Current Prices)
B5: Table 1.3: GDP Income Components
B6: Table 1.4: Nominal GDP (non-seasonally adjusted)
B7: Table 1.5: Per capita (age +16)
B8: Table 1.6: Labour Market
B9: Table 1.7: Inflation
B10: Table 1.8: Balance of Payments
B11: Table 1.9: Market-derived assumptions
B12: Table 1.10: Financial Balances by Sector
B13: Table 1.11: Balance Sheets and Lending
... B24: Table 1.20 Electricity price forecast

Sheet 1.1
A1: Back to contents
B2: 1.1 GDP expenditure components (£ billion chain-linked volumes, seasonally adjusted)
C3: Private consumption | D3: Government consumption | E3: Fixed investment | J3: Net acquisition of valuables | K3: Final domestic demand | L3: Change in inventories | M3: Total domestic demand | N3: Exports | O3: Total final expenditure | P3: Imports | Q3: Statistical discrepancy | R3: Real GDP | S3: Non-oil GVA
E4: of which: | F4: Business investment | G4: Private dwellings | H4: General government | I4: Public corps dwellings
B5: 2008Q1 | C5: 366.795 | D5: 115.993 | E5: 101.666 | F5: 52.099 | G5: 31.883 | H5: 16.775 | I5: 1.784 | J5: 0.505 | K5: 584.959 | L5: -4.672 | M5: 580.287 | N5: 168.251 | O5: 756.225 | P5: 169.186 | Q5: 0 | R5: 586.69 | S5: 513.251
B6: 2008Q2 | C6: 362.064 | D6: 115.307 | E6: 103.272 | F6: 57.108 | G6: 30.069 | H6: 15.255 | I6: 1.66 | J6: -0.216 | K6: 580.427 | L6: -0.281 | M6: 580.146 | N6: 168.428 | O6: 752.599 | P6: 168.738 | Q6: 0 | R6: 583.541 | S6: 511.331
B7: 2008Q3 | C7: 356.567 | D7: 117.362 | E7: 98.198 | F7: 54.942 | G7: 24.559 | H7: 15.861 | I7: 3.419 | J7: -1.304 | K7: 570.823 | L7: -0.858 | M7: 569.965 | N7: 169.106 | O7: 738.868 | P7: 164.573 | Q7: 0 | R7: 573.961 | S7: 503.224
B8: 2008Q4 | C8: 347.875 | D8: 118.565 | E8: 96.036 | F8: 52.434 | G8: 23.384 | H8: 17.411 | I8: 3.329 | J8: 0.241 | K8: 562.717 | L8: -2.768 | M8: 559.949 | N8: 161.069 | O8: 717.793 | P8: 155.485 | Q8: 0 | R8: 561.816 | S8: 492.727
B9: 2009Q1 | C9: 346.435 | D9: 117.859 | E9: 90.795 | F9: 48.456 | G9: 21.958 | H9: 17.521 | I9: 3.285 | J9: 1.402 | K9: 556.491 | L9: -7.604 | M9: 548.887 | N9: 152.669 | O9: 700.234 | P9: 149.466 | Q9: 0 | R9: 550.451 | S9: 483.023
B10: 2009Q2 | C10: 345.972 | D10: 117.61 | E10: 87.418 | F10: 46.751 | G10: 21.178 | H10: 16.507 | I10: 3.256 | J10: 0.533 | K10: 551.533 | L10: -7.752 | M10: 543.781 | N10: 151.805 | O10: 698.826 | P10: 149.706 | Q10: 0 | R10: 548.859 | S10: 480.942
B11: 2009Q3 | C11: 347.113 | D11: 118.717 | E11: 87.976 | F11: 45.581 | G11: 21.321 | H11: 18.129 | I11: 3.289 | J11: 0.773 | K11: 554.579 | L11: -8.53 | M11: 546.049 | N11: 151.597 | O11: 703.47 | P11: 153.651 | Q11: 0 | R11: 549.54 | S11: 482.029
B12: 2009Q4 | C12: 349.909 | D12: 119.548 | E12: 86.66 | F12: 45.414 | G12: 20.128 | H12: 17.924 | I12: 3.378 | J12: -0.322 | K12: 555.795 | L12: -5.121 | M12: 550.674 | N12: 157.882 | O12: 709.156 | P12: 157.472 | Q12: 0 | R12: 551.372 | S12: 484.18
B13: 2010Q1 | C13: 349.45 | D13: 117.946 | E13: 90.007 | F13: 47.159 | G13: 20.935 | H13: 18.677 | I13: 3.422 | J13: -0.48 | K13: 556.923 | L13: -2.406 | M13: 554.517 | N13: 157.938 | O13: 715.447 | P13: 159.135 | Q13: 0 | R13: 556.002 | S13: 488.699
B14: 2010Q2 | C14: 358.968 | D14: 118.254 | E14: 87.938 | F14: 46.055 | G14: 21.505 | H14: 17.329 | I14: 3.4 | J14: -0.745 | K14: 564.415 | L14: -1.128 | M14: 563.287 | N14: 162.473 | O14: 726.669 | P14: 163.978 | Q14: 0 | R14: 562.353 | S14: 494.936
B15: 2010Q3 | C15: 359.801 | D15: 118.609 | E15: 90.701 | F15: 47.527 | G15: 22.204 | H15: 17.948 | I15: 3.383 | J15: 0.346 | K15: 569.457 | L15: -0.989 | M15: 568.468 | N15: 164.197 | O15: 735.142 | P15: 169.102 | Q15: 0 | R15: 565.659 | S15: 498.167
B16: 2010Q4 | C16: 358.905 | D16: 118.817 | E16: 92.57 | F16: 50.337 | G16: 21.612 | H16: 17.522 | I16: 3.262 | J16: 0.364 | K16: 570.656 | L16: -2.502 | M16: 568.154 | N16: 167.102 | O16: 737.228 | P16: 170.871 | Q16: 0 | R16: 565.945 | S16: 498.906
... B101: 2032Q1 | C101: 473.59318 | D101: 164.04245 | E101: 151.74559 | F101: 81.741768 | G101: 40.515358 | H101: 26.961891 | I101: 2.5265711 | J101: 4.162 | K101: 793.54321 | L101: 1.4223616 | M101: 794.96557 | N101: 244.1829 | O101: 1039.1485 | P101: 261.05619 | Q101: -0.692 | R101: 777.40028 | S101: 703.06406
B102: 2008 | C102: 1433.301 | D102: 467.227 | E102: 399.172 | F102: 216.583 | G102: 109.895 | H102: 65.302 | I102: 10.192 | J102: -0.774 | K102: 2298.926 | L102: -8.579 | M102: 2290.347 | N102: 666.854 | O102: 2965.485 | P102: 657.982 | Q102: 0 | R102: 2306.008 | S102: 2020.533
B103: 2009 | C103: 1389.429 | D103: 473.734 | E103: 352.849 | F103: 186.202 | G103: 84.585 | H103: 70.081 | I103: 13.208 | J103: 2.386 | K103: 2218.398 | L103: -29.007 | M103: 2189.391 | N103: 613.953 | O103: 2811.686 | P103: 610.295 | Q103: 0 | R103: 2200.222 | S103: 1930.174
B104: 2010 | C104: 1427.124 | D104: 473.626 | E104: 361.216 | F104: 191.078 | G104: 86.256 | H104: 71.476 | I104: 13.467 | J104: -0.515 | K104: 2261.451 | L104: -7.025 | M104: 2254.426 | N104: 651.71 | O104: 2914.486 | P104: 663.086 | Q104: 0 | R104: 2249.959 | S104: 1980.708
B105: 2011 | C105: 1418.187 | D105: 472.11 | E105: 360.603 | F105: 199.419 | G105: 82.73 | H105: 66.506 | I105: 12.301 | J105: -0.775 | K105: 2250.125 | L105: 0.43 | M105: 2250.555 | N105: 695.989 | O105: 2952.109 | P105: 681.262 | Q105: 0 | R105: 2269.116 | S105: 2007.666
B106: 2012 | C106: 1446.168 | D106: 479.021 | E106: 367.983 | F106: 211.73 | G106: 82.477 | H106: 61.929 | I106: 11.296 | J106: -1.609 | K106: 2291.563 | L106: 4.545 | M106: 2296.108 | N106: 699.711 | O106: 3002.459 | P106: 696.649 | Q106: 0 | R106: 2303.794 | S106: 2049.074
B107: 2013 | C107: 1477.994 | D107: 479.189 | E107: 383.415 | F107: 221.254 | G107: 92.359 | H107: 58.295 | I107: 10.777 | J107: 6.577 | K107: 2347.175 | L107: 0.648 | M107: 2347.823 | N107: 702.7 | O107: 3064.553 | P107: 718.796 | Q107: 0 | R107: 2343.384 | S107: 2087.782
B108: 2014 | C108: 1518.913 | D108: 490.334 | E108: 411.507 | F108: 235.726 | G108: 97.12 | H108: 65.43 | I108: 12.568 | J108: 4.943 | K108: 2425.697 | L108: 20.925 | M108: 2446.622 | N108: 712.184 | O108: 3175.387 | P108: 755.205 | Q108: 0 | R108: 2417.439 | S108: 2155.831
B109: 2015 | C109: 1563.941 | D109: 495.189 | E109: 439.379 | F109: 256.423 | G109: 103.508 | H109: 66.528 | I109: 12.047 | J109: -0.831 | K109: 2497.678 | L109: 8.939 | M109: 2506.617 | N109: 738.202 | O109: 3263.96 | P109: 792.45 | Q109: 0 | R109: 2469.182 | S109: 2195.071
B110: 2016 | C110: 1619.767 | D110: 499.524 | E110: 466.345 | F110: 276.239 | G110: 111.832 | H110: 65.012 | I110: 12.218 | J110: -0.412 | K110: 2585.224 | L110: -15.807 | M110: 2569.417 | N110: 765.88 | O110: 3352.776 | P110: 827.957 | Q110: 0 | R110: 2523.665 | S110: 2244.315
B111: 2017 | C111: 1653.27 | D111: 504.596 | E111: 484.361 | F111: 278.862 | G111: 121.82 | H111: 71.075 | I111: 12.088 | J111: -0.766 | K111: 2641.461 | L111: -6.229 | M111: 2635.232 | N111: 815.172 | O111: 3454.44 | P111: 853.305 | Q111: 0 | R111: 2599.961 | S111: 2315.596
B112: 2018 | C112: 1687.414 | D112: 507.841 | E112: 483.363 | F112: 276.188 | G112: 130.036 | H112: 70.542 | I112: 6.334 | J112: 1.699 | K112: 2680.317 | L112: -1.5 | M112: 2678.817 | N112: 846.41 | O112: 3523.695 | P112: 882.424 | Q112: 0 | R112: 2640.295 | S112: 2348.685
B113: 2019 | C113: 1706.496 | D113: 522.794 | E113: 492.227 | F113: 280.224 | G113: 132.696 | H113: 72.89 | I113: 6.0812308 | J113: 1.436 | K113: 2722.953 | L113: -1.02 | M113: 2721.933 | N113: 862.521 | O113: 3583.95 | P113: 909.625 | Q113: 0 | R113: 2673.465 | S113: 2381.148
... B125: 2031 | C125: 1876.2601 | D125: 650.72528 | E125: 602.49594 | F125: 324.32765 | G125: 159.73015 | H125: 108.50606 | I125: 9.93208 | J125: 16.648 | K125: 3146.1293 | L125: 4.969321 | M125: 3151.0987 | N125: 969.55014 | O125: 4120.6488 | P125: 1036.9715 | Q125: -2.768 | R125: 3080.9093 | S125: 2785.3842
B126: 2008-09 | C126: 1412.941 | D126: 469.093 | E126: 388.301 | F126: 212.94 | G126: 99.97 | H126: 66.048 | I126: 11.693 | J126: 0.123 | K126: 2270.458 | L126: -11.511 | M126: 2258.947 | N126: 651.272 | O126: 2909.494 | P126: 638.262 | Q126: 0 | R126: 2269.769 | S126: 1990.305
B127: 2009-10 | C127: 1392.444 | D127: 473.821 | E127: 352.061 | F127: 184.905 | G127: 83.562 | H127: 71.237 | I127: 13.345 | J127: 0.504 | K127: 2218.83 | L127: -23.809 | M127: 2195.021 | N127: 619.222 | O127: 2826.899 | P127: 619.964 | Q127: 0 | R127: 2205.773 | S127: 1935.85
B128: 2010-11 | C128: 1432.915 | D128: 474.904 | E128: 360.567 | F128: 190.979 | G128: 86.298 | H128: 71.25 | I128: 13.206 | J128: -2.813 | K128: 2265.573 | L128: -4.686 | M128: 2260.887 | N128: 669.16 | O128: 2933.663 | P128: 671.346 | Q128: 0 | R128: 2260.83 | S128: 1992.087
B129: 2011-12 | C129: 1417.864 | D129: 474.358 | E129: 364.452 | F129: 206.141 | G129: 81.576 | H129: 64.597 | I129: 11.977 | J129: -0.13 | K129: 2256.544 | L129: -5.038 | M129: 2251.506 | N129: 701.65 | O129: 2964.894 | P129: 687.367 | Q129: 0 | R129: 2275.659 | S129: 2016.794
B130: 2012-13 | C130: 1456.88 | D130: 476.464 | E130: 367.582 | F130: 211.68 | G130: 84.167 | H130: 59.997 | I130: 11.248 | J130: 1.278 | K130: 2302.204 | L130: 9.344 | M130: 2311.548 | N130: 694.342 | O130: 3008.674 | P130: 696.599 | Q130: 0 | R130: 2310.127 | S130: 2056.462
B131: 2013-14 | C131: 1485.969 | D131: 482.447 | E131: 391.595 | F131: 224.303 | G131: 95.087 | H131: 60.709 | I131: 10.787 | J131: 6.848 | K131: 2366.859 | L131: 1.477 | M131: 2368.336 | N131: 702.864 | O131: 3091.332 | P131: 728.399 | Q131: 0 | R131: 2360.331 | S131: 2102.784
B132: 2014-15 | C132: 1532.817 | D132: 490.519 | E132: 420.537 | F132: 242.948 | G132: 97.726 | H132: 66.023 | I132: 13.09 | J132: 6.385 | K132: 2450.258 | L132: 25.945 | M132: 2476.203 | N132: 717.582 | O132: 3207.738 | P132: 771.184 | Q132: 0 | R132: 2433.819 | S132: 2170.395
B133: 2015-16 | C133: 1577.102 | D133: 497.553 | E133: 442.761 | F133: 261.559 | G133: 105.417 | H133: 63.153 | I133: 11.724 | J133: -2.874 | K133: 2514.542 | L133: -1.845 | M133: 2512.697 | N133: 745.131 | O133: 3280.497 | P133: 797.216 | Q133: 0 | R133: 2481.205 | S133: 2204.23
B134: 2016-17 | C134: 1630.199 | D134: 500.049 | E134: 471.326 | F134: 276.504 | G134: 114.953 | H134: 66.582 | I134: 12.315 | J134: -1.797 | K134: 2599.777 | L134: -12.356 | M134: 2587.421 | N134: 776.567 | O134: 3375.12 | P134: 832.926 | Q134: 0 | R134: 2541.029 | S134: 2261.286
B135: 2017-18 | C135: 1661.473 | D135: 505.834 | E135: 488.823 | F135: 280.546 | G135: 123.854 | H135: 73.337 | I135: 10.667 | J135: 0.262 | K135: 2656.392 | L135: -6.743 | M135: 2649.649 | N135: 825.668 | O135: 3476.53 | P135: 860.204 | Q135: 0 | R135: 2615.239 | S135: 2328.357
...

Sheet 1.2
A1: Back to contents
B2: 1.2 GDP expenditure components (£ billion current prices, seasonally adjusted)
C3: Private consumption | D3: Government consumption | E3: Fixed investment | G3: Net acquisition of valuables | H3: Final domestic demand | I3: Change in inventories | J3: Total domestic demand | K3: Exports | L3: Total final expenditure | M3: Imports | N3: Statistical discrepancy | O3: GDP at market prices | P3: Gross national income
E4: of which: | F4: General government
B5: 2008Q1 | C5: 254.939 | D5: 79.563 | E5: 74.277 | F5: 12.181 | G5: 0.314 | H5: 409.093 | I5: 0.18 | J5: 409.273 | K5: 105.083 | L5: 514.356 | M5: 114.64 | N5: 0 | O5: 399.716 | P5: 399.097
B6: 2008Q2 | C6: 255.557 | D6: 79.825 | E6: 76.1 | F6: 11.29 | G6: -0.157 | H6: 411.325 | I6: -0.41 | J6: 410.915 | K6: 110.79 | L6: 521.705 | M6: 119.018 | N6: 0 | O6: 402.687 | P6: 397.924
B7: 2008Q3 | C7: 255.126 | D7: 80.711 | E7: 72.954 | F7: 11.788 | G7: -0.657 | H7: 408.134 | I7: 0.503 | J7: 408.637 | K7: 113.068 | L7: 521.705 | M7: 119.568 | N7: 0 | O7: 402.137 | P7: 397.712
B8: 2008Q4 | C8: 247.459 | D8: 82.893 | E8: 71.679 | F8: 12.839 | G8: 0.281 | H8: 402.312 | I8: -2.04 | J8: 400.272 | K8: 109.737 | L8: 510.009 | M8: 112.332 | N8: 0 | O8: 397.677 | P8: 386.453
B9: 2009Q1 | C9: 247.016 | D9: 83.663 | E9: 68.481 | F9: 13.247 | G9: 1.249 | H9: 400.409 | I9: -5.806 | J9: 394.603 | K9: 103.777 | L9: 498.38 | M9: 108.605 | N9: 0 | O9: 389.775 | P9: 382.791
B10: 2009Q2 | C10: 247.047 | D10: 83.757 | E10: 65.661 | F10: 12.177 | G10: 0.525 | H10: 396.99 | I10: -3.24 | J10: 393.75 | K10: 101.784 | L10: 495.534 | M10: 106.383 | N10: 0 | O10: 389.151 | P10: 383.333
B11: 2009Q3 | C11: 248.1 | D11: 85.714 | E11: 66.14 | F11: 13.441 | G11: 0.567 | H11: 400.521 | I11: -3.5 | J11: 397.021 | K11: 102.676 | L11: 499.697 | M11: 108.518 | N11: 0 | O11: 391.179 | P11: 392.017
B12: 2009Q4 | C12: 248.74 | D12: 85.393 | E12: 64.643 | F12: 13.095 | G12: -0.012 | H12: 398.764 | I12: -5.412 | J12: 393.352 | K12: 108.239 | L12: 501.591 | M12: 112.291 | N12: 0 | O12: 389.3 | P12: 388.252
B13: 2010Q1 | C13: 248.576 | D13: 86.36 | E13: 66.662 | F13: 13.45 | G13: -0.258 | H13: 401.34 | I13: 2.097 | J13: 403.437 | K13: 110.63 | L13: 514.067 | M13: 115.941 | N13: 0 | O13: 398.126 | P13: 398.272
B14: 2010Q2 | C14: 257.23 | D14: 86.009 | E14: 65.37 | F14: 12.504 | G14: -0.362 | H14: 408.247 | I14: -0.069 | J14: 408.178 | K14: 116.022 | L14: 524.2 | M14: 121.263 | N14: 0 | O14: 402.937 | P14: 403.384
B15: 2010Q3 | C15: 259.625 | D15: 86.02 | E15: 67.39 | F15: 12.903 | G15: 0.443 | H15: 413.478 | I15: 0.516 | J15: 413.994 | K15: 116.673 | L15: 530.667 | M15: 124.49 | N15: 0 | O15: 406.177 | P15: 405.649
B16: 2010Q4 | C16: 261.581 | D16: 87.098 | E16: 68.691 | F16: 12.449 | G16: 0.574 | H16: 417.944 | I16: -2.532 | J16: 415.412 | K16: 121.17 | L16: 536.582 | M16: 127.983 | N16: 0 | O16: 408.599 | P16: 409.241
... B101: 2032Q1 | C101: 587.65387 | D101: 198.96622 | E101: 178.58878 | F101: 32.528326 | G101: 4.7625579 | H101: 969.97143 | I101: 1.3916884 | J101: 971.36312 | K101: 280.47456 | L101: 1251.8377 | M101: 288.78165 | N101: -0.85648292 | O101: 962.19955 | P101: 952.31909
B102: 2008 | C102: 1013.081 | D102: 322.992 | E102: 295.01 | F102: 48.098 | G102: -0.219 | H102: 1630.864 | I102: -1.767 | J102: 1629.097 | K102: 438.678 | L102: 2067.775 | M102: 465.558 | N102: 0 | O102: 1602.217 | P102: 1581.186
B103: 2009 | C103: 990.903 | D103: 338.527 | E103: 264.925 | F103: 51.96 | G103: 2.329 | H103: 1596.684 | I103: -17.958 | J103: 1578.726 | K103: 416.476 | L103: 1995.202 | M103: 435.797 | N103: 0 | O103: 1559.405 | P103: 1546.393
B104: 2010 | C104: 1027.012 | D104: 345.487 | E104: 268.113 | F104: 51.306 | G104: 0.397 | H104: 1641.009 | I104: 0.012 | J104: 1641.021 | K104: 464.495 | L104: 2105.516 | M104: 489.677 | N104: 0 | O104: 1615.839 | P104: 1616.546
B105: 2011 | C105: 1060.307 | D105: 347.499 | E105: 270.216 | F105: 47.833 | G105: 1.049 | H105: 1679.071 | I105: 4.137 | J105: 1683.208 | K105: 522.107 | L105: 2205.315 | M105: 535.37 | N105: 0 | O105: 1669.945 | P105: 1676.89
B106: 2012 | C106: 1099.217 | D106: 354.855 | E106: 280.159 | F106: 45.52 | G106: 0.217 | H106: 1734.448 | I106: 3.957 | J106: 1738.405 | K106: 525.113 | L106: 2263.518 | M106: 541.81 | N106: 0 | O106: 1721.708 | P106: 1705.748
B107: 2013 | C107: 1148.293 | D107: 356.935 | E107: 296.889 | F107: 43.729 | G107: 7.139 | H107: 1809.256 | I107: 3.151 | J107: 1812.407 | K107: 540.436 | L107: 2352.843 | M107: 563.771 | N107: 0 | O107: 1789.072 | P107: 1757.503
B108: 2014 | C108: 1194.143 | D108: 368.248 | E108: 322.1 | F108: 50.207 | G108: 6.017 | H108: 1890.508 | I108: 17.503 | J108: 1908.011 | K108: 534.994 | L108: 2443.005 | M108: 567.939 | N108: 0 | O108: 1875.066 | P108: 1841.794
B109: 2015 | C109: 1225.459 | D109: 372.7 | E109: 346.078 | F109: 51.638 | G109: 0.81 | H109: 1945.047 | I109: 9.323 | J109: 1954.37 | K109: 537.513 | L109: 2491.883 | M109: 563.867 | N109: 0 | O109: 1928.016 | P109: 1886.247
B110: 2016 | C110: 1285.036 | D110: 381.332 | E110: 372.262 | F110: 51.356 | G110: 1.341 | H110: 2039.971 | I110: -0.806 | J110: 2039.165 | K110: 582.613 | L110: 2621.778 | M110: 617.023 | N110: 0 | O110: 2004.755 | P110: 1958.022
B111: 2017 | C111: 1334.709 | D111: 387.331 | E111: 397.794 | F111: 57.575 | G111: 0.664 | H111: 2120.498 | I111: 2.777 | J111: 2123.275 | K111: 649.59 | L111: 2772.865 | M111: 675.643 | N111: 0 | O111: 2097.222 | P111: 2074.819
B112: 2018 | C112: 1389.908 | D112: 397.819 | E112: 405.867 | F112: 58.385 | G112: 2.564 | H112: 2196.158 | I112: 1.475 | J112: 2197.633 | K112: 691.74 | L112: 2889.373 | M112: 717.814 | N112: 0 | O112: 2171.559 | P112: 2142.305
B113: 2019 | C113: 1425.544 | D113: 425.699 | E113: 424.262 | F113: 62.246 | G113: 2.582 | H113: 2278.087 | I113: 1.861 | J113: 2279.948 | K113: 718.759 | L113: 2998.707 | M113: 745.746 | N113: 0 | O113: 2252.961 | P113: 2250.702
... B125: 2031 | C125: 2299.5554 | D125: 782.74731 | E125: 701.93424 | F125: 128.96568 | G125: 19.347404 | H125: 3803.5843 | I125: 4.8071886 | J125: 3808.3915 | K125: 1101.5655 | L125: 4909.957 | M125: 1136.4648 | N125: -3.3871141 | O125: 3770.1051 | P125: 3731.3875
B126: 2008-09 | C126: 1005.158 | D126: 327.092 | E126: 289.214 | F126: 49.164 | G126: 0.716 | H126: 1622.18 | I126: -7.753 | J126: 1614.427 | K126: 437.372 | L126: 2051.799 | M126: 459.523 | N126: 0 | O126: 1592.276 | P126: 1564.88
B127: 2009-10 | C127: 992.463 | D127: 341.224 | E127: 263.106 | F127: 52.163 | G127: 0.822 | H127: 1597.615 | I127: -10.055 | J127: 1587.56 | K127: 423.329 | L127: 2010.889 | M127: 443.133 | N127: 0 | O127: 1567.756 | P127: 1561.874
B128: 2010-11 | C128: 1041.899 | D128: 348.11 | E128: 267.9 | F128: 51.138 | G128: -1.04 | H128: 1656.869 | I128: -3.154 | J128: 1653.715 | K128: 482.822 | L128: 2136.537 | M128: 502.303 | N128: 0 | O128: 1634.234 | P128: 1636.499
B129: 2011-12 | C129: 1065.828 | D129: 349.131 | E129: 274.396 | F129: 46.127 | G129: 1.557 | H129: 1690.912 | I129: 2.817 | J129: 1693.729 | K129: 529.283 | L129: 2223.012 | M129: 542.935 | N129: 0 | O129: 1680.077 | P129: 1682.844
B130: 2012-13 | C130: 1112.428 | D130: 353.227 | E130: 280.71 | F130: 44.755 | G130: 2.297 | H130: 1748.662 | I130: 5.174 | J130: 1753.836 | K130: 524.54 | L130: 2278.376 | M130: 543.283 | N130: 0 | O130: 1735.093 | P130: 1710.732
B131: 2013-14 | C131: 1159.003 | D131: 360.299 | E131: 304.383 | F131: 45.922 | G131: 7.604 | H131: 1831.289 | I131: 6.23 | J131: 1837.519 | K131: 538.348 | L131: 2375.867 | M131: 566.151 | N131: 0 | O131: 1809.716 | P131: 1783.162
B132: 2014-15 | C132: 1203.786 | D132: 368.998 | E132: 329.509 | F132: 50.694 | G132: 7.102 | H132: 1909.395 | I132: 19.405 | J132: 1928.8 | K132: 535.152 | L132: 2463.952 | M132: 571.552 | N132: 0 | O132: 1892.4 | P132: 1854.969
B133: 2015-16 | C133: 1238.243 | D133: 374.606 | E133: 349.576 | F133: 49.42 | G133: -0.851 | H133: 1961.574 | I133: 4.835 | J133: 1966.409 | K133: 541.98 | L133: 2508.389 | M133: 565.745 | N133: 0 | O133: 1942.644 | P133: 1896.09
B134: 2016-17 | C134: 1299.243 | D134: 383.073 | E134: 378.293 | F134: 52.926 | G134: -0.204 | H134: 2060.405 | I134: 1.992 | J134: 2062.397 | K134: 603.394 | L134: 2665.791 | M134: 636.374 | N134: 0 | O134: 2029.417 | P134: 1992.981
B135: 2017-18 | C135: 1348.299 | D135: 389.044 | E135: 403.7 | F135: 59.458 | G135: 1.619 | H135: 2142.662 | I135: -0.969 | J135: 2141.693 | K135: 658.297 | L135: 2799.99 | M135: 684.911 | N135: 0 | O135: 2115.079 | P135: 2088.597
...

Sheet 1.3
A1: Back to contents
B2: 1.3 GDP income components (£ billion current prices, seasonally adjusted)
C3: Labour income | D3: Non-oil PNFC profits | E3: Other income | F3: Gross value added at factor cost | G3: Taxes on products and production less subsidies | H3: Statistical discrepancy (income) | I3: GDP at market prices
B4: 2008Q1 | C4: 191.746 | D4: 61.086 | E4: =F4-C4-D4-H4 -> 103.531 | F4: 356.363 | G4: 43.353 | H4: 0 | I4: 399.716
B5: 2008Q2 | C5: 190.831 | D5: 67.079 | E5: =F5-C5-D5-H5 -> 100.416 | F5: 358.326 | G5: 44.361 | H5: 0 | I5: 402.687
B6: 2008Q3 | C6: 189.702 | D6: 68.516 | E6: =F6-C6-D6-H6 -> 102.043 | F6: 360.261 | G6: 41.876 | H6: 0 | I6: 402.137
B7: 2008Q4 | C7: 188.656 | D7: 63.414 | E7: =F7-C7-D7-H7 -> 105.777 | F7: 357.847 | G7: 39.83 | H7: 0 | I7: 397.677
B8: 2009Q1 | C8: 186.006 | D8: 59.159 | E8: =F8-C8-D8-H8 -> 106.994 | F8: 352.159 | G8: 37.616 | H8: 0 | I8: 389.775
B9: 2009Q2 | C9: 188.824 | D9: 56.745 | E9: =F9-C9-D9-H9 -> 104.852 | F9: 350.421 | G9: 38.73 | H9: 0 | I9: 389.151
B10: 2009Q3 | C10: 188.143 | D10: 64.034 | E10: =F10-C10-D10-H10 -> 98.625 | F10: 350.802 | G10: 40.377 | H10: 0 | I10: 391.179
B11: 2009Q4 | C11: 188.557 | D11: 52.774 | E11: =F11-C11-D11-H11 -> 107.016 | F11: 348.347 | G11: 40.953 | H11: 0 | I11: 389.3
B12: 2010Q1 | C12: 188.728 | D12: 57.754 | E12: =F12-C12-D12-H12 -> 107.253 | F12: 353.735 | G12: 44.391 | H12: 0 | I12: 398.126
B13: 2010Q2 | C13: 189.62 | D13: 59.339 | E13: =F13-C13-D13-H13 -> 105.209 | F13: 354.168 | G13: 48.769 | H13: 0 | I13: 402.937
B14: 2010Q3 | C14: 191.153 | D14: 62.308 | E14: =F14-C14-D14-H14 -> 107.581 | F14: 361.042 | G14: 45.135 | H14: 0 | I14: 406.177
B15: 2010Q4 | C15: 192.214 | D15: 65.584 | E15: =F15-C15-D15-H15 -> 105.386 | F15: 363.184 | G15: 45.415 | H15: 0 | I15: 408.599
... B100: 2032Q1 | C100: 434.11094 | D100: 166.34066 | E100: =F100-C100-D100-H100 -> 262.65025 | F100: 860.60784 | G100: 101.5917 | H100: -2.494 | I100: 962.19955
B101: 2008 | C101: 760.935 | D101: 260.095 | E101: =F101-C101-D101-H101 -> 411.767 | F101: 1432.797 | G101: 169.42 | H101: 0 | I101: 1602.217
B102: 2009 | C102: 751.53 | D102: 232.712 | E102: =F102-C102-D102-H102 -> 417.487 | F102: 1401.729 | G102: 157.676 | H102: 0 | I102: 1559.405
B103: 2010 | C103: 761.715 | D103: 244.985 | E103: =F103-C103-D103-H103 -> 425.429 | F103: 1432.129 | G103: 183.71 | H103: 0 | I103: 1615.839
B104: 2011 | C104: 777.882 | D104: 254.295 | E104: =F104-C104-D104-H104 -> 437.161 | F104: 1469.338 | G104: 200.607 | H104: 0 | I104: 1669.945
B105: 2012 | C105: 789.833 | D105: 268.518 | E105: =F105-C105-D105-H105 -> 456.754 | F105: 1515.105 | G105: 206.603 | H105: 0 | I105: 1721.708
B106: 2013 | C106: 826.706 | D106: 281.556 | E106: =F106-C106-D106-H106 -> 463.186 | F106: 1571.448 | G106: 217.624 | H106: 0 | I106: 1789.072
B107: 2014 | C107: 861.13 | D107: 315.1 | E107: =F107-C107-D107-H107 -> 470.646 | F107: 1646.876 | G107: 228.19 | H107: 0 | I107: 1875.066
B108: 2015 | C108: 892.489 | D108: 325.7 | E108: =F108-C108-D108-H108 -> 476.157 | F108: 1694.346 | G108: 233.67 | H108: 0 | I108: 1928.016
B109: 2016 | C109: 923.663 | D109: 337.323 | E109: =F109-C109-D109-H109 -> 501.763 | F109: 1762.749 | G109: 242.006 | H109: 0 | I109: 2004.755
B110: 2017 | C110: 967.03 | D110: 354.319 | E110: =F110-C110-D110-H110 -> 523.4 | F110: 1844.749 | G110: 252.473 | H110: 0 | I110: 2097.222
B111: 2018 | C111: 1005.821 | D111: 367.031 | E111: =F111-C111-D111-H111 -> 539.527 | F111: 1912.379 | G111: 259.18 | H111: 0 | I111: 2171.559
B112: 2019 | C112: 1046.611 | D112: 377.657 | E112: =F112-C112-D112-H112 -> 563.195 | F112: 1987.463 | G112: 265.498 | H112: 0 | I112: 2252.961
... B124: 2031 | C124: 1704.1682 | D124: 650.13631 | E124: =F124-C124-D124-H124 -> 1026.8688 | F124: 3371.1974 | G124: 398.90772 | H124: -9.976 | I124: 3770.1051
B125: 2008-09 | C125: 755.195 | D125: 258.168 | E125: =F125-C125-D125-H125 -> 415.23 | F125: 1428.593 | G125: 163.683 | H125: 0 | I125: 1592.276
B126: 2009-10 | C126: 754.252 | D126: 231.307 | E126: =F126-C126-D126-H126 -> 417.746 | F126: 1403.305 | G126: 164.451 | H126: 0 | I126: 1567.756
B127: 2010-11 | C127: 769.119 | D127: 251.331 | E127: =F127-C127-D127-H127 -> 424.608 | F127: 1445.058 | G127: 189.176 | H127: 0 | I127: 1634.234
B128: 2011-12 | C128: 777.862 | D128: 255.264 | E128: =F128-C128-D128-H128 -> 444.423 | F128: 1477.549 | G128: 202.528 | H128: 0 | I128: 1680.077
B129: 2012-13 | C129: 793.358 | D129: 276.714 | E129: =F129-C129-D129-H129 -> 456.878 | F129: 1526.95 | G129: 208.143 | H129: 0 | I129: 1735.093
B130: 2013-14 | C130: 842.425 | D130: 281.338 | E130: =F130-C130-D130-H130 -> 464.487 | F130: 1588.25 | G130: 221.466 | H130: 0 | I130: 1809.716
B131: 2014-15 | C131: 865.081 | D131: 324.665 | E131: =F131-C131-D131-H131 -> 473.755 | F131: 1663.501 | G131: 228.899 | H131: 0 | I131: 1892.4
B132: 2015-16 | C132: 901.425 | D132: 325.931 | E132: =F132-C132-D132-H132 -> 479.148 | F132: 1706.504 | G132: 236.14 | H132: 0 | I132: 1942.644
B133: 2016-17 | C133: 931.849 | D133: 341.806 | E133: =F133-C133-D133-H133 -> 511.805 | F133: 1785.46 | G133: 243.957 | H133: 0 | I133: 2029.417
B134: 2017-18 | C134: 979.732 | D134: 356.425 | E134: =F134-C134-D134-H134 -> 525.608 | F134: 1861.765 | G134: 253.314 | H134: 0 | I134: 2115.079
B135: 2018-19 | C135: 1014.142 | D135: 367.389 | E135: =F135-C135-D135-H135 -> 546.638 | F135: 1928.169 | G135: 262.211 | H135: 0 | I135: 2190.38
...

Sheet 1.4
A1: Back to contents
B2: 1.4 Nominal GDP (£ billion, non-seasonally adjusted)
B3: 2008Q1 | C3: 397.265
B4: 2008Q2 | C4: 397.113
B5: 2008Q3 | C5: 404.265
B6: 2008Q4 | C6: 403.574
B7: 2009Q1 | C7: 388.315
B8: 2009Q2 | C8: 380.351
B9: 2009Q3 | C9: 394.53
B10: 2009Q4 | C10: 396.209
B11: 2010Q1 | C11: 395.98
B12: 2010Q2 | C12: 394.997
B13: 2010Q3 | C13: 409.292
B14: 2010Q4 | C14: 415.57
... B99: 2032Q1 | C99: 964.54755
B100: Calendar Year
B101: 2008 | C101: 1602.217
B102: 2009 | C102: 1559.405
B103: 2010 | C103: 1615.839
B104: 2011 | C104: 1669.945
B105: 2012 | C105: 1721.708
B106: 2013 | C106: 1789.072
B107: 2014 | C107: 1875.066
B108: 2015 | C108: 1928.016
B109: 2016 | C109: 2004.755
B110: 2017 | C110: 2097.222
B111: 2018 | C111: 2171.559
B112: 2019 | C112: 2252.961
... B124: 2031 | C124: 3770.1051
B125: Centred end-March
B126: 2008-09 | C126: =SUM(OFFSET(C$6,4*(ROW()-ROW(C$126)),0, 4, 1)) -> 1566.77
B127: 2009-10 | C127: =SUM(OFFSET(C$6,4*(ROW()-ROW(C$126)),0, 4, 1)) -> 1596.478
B128: 2010-11 | C128: =SUM(OFFSET(C$6,4*(ROW()-ROW(C$126)),0, 4, 1)) -> 1654.846
B129: 2011-12 | C129: =SUM(OFFSET(C$6,4*(ROW()-ROW(C$126)),0, 4, 1)) -> 1706.949
B130: 2012-13 | C130: =SUM(OFFSET(C$6,4*(ROW()-ROW(C$126)),0, 4, 1)) -> 1770.435
B131: 2013-14 | C131: =SUM(OFFSET(C$6,4*(ROW()-ROW(C$126)),0, 4, 1)) -> 1855.01
B132: 2014-15 | C132: =SUM(OFFSET(C$6,4*(ROW()-ROW(C$126)),0, 4, 1)) -> 1914.717
B133: 2015-16 | C133: =SUM(OFFSET(C$6,4*(ROW()-ROW(C$126)),0, 4, 1)) -> 1979.243
B134: 2016-17 | C134: =SUM(OFFSET(C$6,4*(ROW()-ROW(C$126)),0, 4, 1)) -> 2072.938
B135: 2017-18 | C135: =SUM(OFFSET(C$6,4*(ROW()-ROW(C$126)),0, 4, 1)) -> 2153.988
...

Sheet 1.5
A1: Back to contents
B2: 1.5 Per person
C3: By total population | H3: Ages 16+
C4: Index: 2008Q1=100 | G4: £ thousands (2023 prices) | H4: Index: 2008Q1=100 | L4: £ thousands (2023 prices)
C5: LFS employment | D5: Real household disposable income | E5: Real consumption | F5: Real GDP | G5: Real household disposable income | H5: LFS employment | I5: Real household disposable income | J5: Real consumption | K5: Real GDP | L5: Real household disposable income
B6: 2008Q1 | C6: 100 | D6: 100 | E6: 100 | F6: 100 | G6: 5.8449545 | H6: 100 | I6: 100 | J6: 100 | K6: 100 | L6: 7.3301624
B7: 2008Q2 | C7: 99.92395 | D7: 100.80489 | E7: 98.509003 | F7: 99.26055 | G7: 5.8919999 | H7: 99.888431 | I7: 100.76906 | J7: 98.473987 | K7: 99.225266 | L7: 7.3865355
B8: 2008Q3 | C8: 99.27153 | D8: 98.999832 | E8: 96.84266 | F8: 97.459161 | G8: 5.7864951 | H8: 99.201997 | I8: 98.930489 | J8: 96.774828 | K8: 97.390897 | L8: 7.2517655
B9: 2008Q4 | C9: 98.922915 | D9: 100.68398 | E9: 94.315943 | F9: 95.229327 | G9: 5.8849328 | H9: 98.831618 | I9: 100.59106 | J9: 94.228897 | K9: 95.141438 | L9: 7.3734879
B10: 2009Q1 | C10: 98.207654 | D10: 99.384544 | E10: 93.760803 | F10: 93.139295 | G10: 5.8089814 | H10: 98.095254 | I10: 99.270797 | J10: 93.653493 | K10: 93.032695 | L10: 7.2767107
B11: 2009Q2 | C11: 97.102744 | D11: 101.79117 | E11: 93.470064 | F11: 92.705841 | G11: 5.9496475 | H11: 96.973684 | I11: 101.65588 | J11: 93.345832 | K11: 92.582625 | L11: 7.4515409
B12: 2009Q3 | C12: 96.849766 | D12: 100.9674 | E12: 93.591925 | F12: 92.63637 | G12: 5.9014988 | H12: 96.703583 | I12: 100.81501 | J12: 93.450659 | K12: 92.496547 | L12: 7.3899037
B13: 2009Q4 | C13: 96.765824 | D13: 101.84332 | E13: 94.157148 | F13: 92.759331 | G13: 5.9526956 | H13: 96.596207 | I13: 101.6648 | J13: 93.992103 | K13: 92.596737 | L13: 7.452195
B14: 2010Q1 | C14: 96.27737 | D14: 101.59637 | E14: 93.845973 | F14: 93.35158 | G14: 5.9382614 | H14: 96.087191 | I14: 101.39568 | J14: 93.660597 | K14: 93.16718 | L14: 7.4324681
B15: 2010Q2 | C15: 96.678428 | D15: 101.90924 | E15: 96.210059 | F15: 94.229846 | G15: 5.9565488 | H15: 96.464121 | I15: 101.68334 | J15: 95.996791 | K15: 94.020968 | L15: 7.453554
B16: 2010Q3 | C16: 97.114898 | D16: 101.15969 | E16: 96.232451 | F16: 94.586379 | G16: 5.9127379 | H16: 96.883604 | I16: 100.91876 | J16: 96.003258 | K16: 94.361108 | L16: 7.3975093
B17: 2010Q4 | C17: 96.71185 | D17: 100.07147 | E17: 95.793272 | F17: 94.437492 | G17: 5.849132 | H17: 96.461805 | I17: 99.812742 | J17: 95.545601 | K17: 94.193327 | L17: 7.3164361
... B102: 2032Q1 | C102: 104.72812 | D102: 115.11885 | E102: 113.07774 | F102: 116.04624 | G102: 6.7286443 | H102: 100.43781 | I102: 110.40288 | J102: 108.44538 | K102: 111.29228 | L102: 8.0927101
C103: Index: 2008=100 | H103: Index: 2008=100
B104: 2008 | C104: 100 | D104: 100 | E104: 100 | F104: 100 | G104: 23.408397 | H104: 100 | I104: 100 | J104: 100 | K104: 100 | L104: 29.341943
B105: 2009 | C105: 97.690817 | D105: 100.87484 | E105: 96.235304 | F105: 94.719884 | G105: 23.613184 | H105: 97.599044 | I105: 100.78008 | J105: 96.144898 | K105: 94.630902 | L105: 29.570834
B106: 2010 | C106: 97.153956 | D106: 101.05928 | E106: 98.059106 | F106: 96.089829 | G106: 23.656358 | H106: 96.979497 | I106: 100.87781 | J106: 97.883022 | K106: 95.917281 | L106: 29.59951
B107: 2011 | C107: 96.882124 | D107: 97.842659 | E107: 96.668024 | F107: 96.135244 | G107: 22.903398 | H107: 96.642956 | I107: 97.60112 | J107: 96.429384 | K107: 95.89792 | L107: 28.638065
B108: 2012 | C108: 97.345834 | D108: 99.558625 | E108: 97.90745 | F108: 96.943172 | G108: 23.305078 | H108: 97.092182 | I108: 99.299207 | J108: 97.652334 | K108: 96.690569 | L108: 29.136317
B109: 2013 | C109: 97.898582 | D109: 100.67303 | E109: 99.380627 | F109: 97.937523 | G109: 23.565943 | H109: 97.617333 | I109: 100.38381 | J109: 99.09512 | K109: 97.656162 | L109: 29.454561
B110: 2014 | C110: 99.508474 | D110: 102.28292 | E110: 101.38116 | F110: 100.28973 | G110: 23.942792 | H110: 99.201392 | I110: 101.96728 | J110: 101.0683 | K110: 99.980239 | L110: 29.919181
B111: 2015 | C111: 100.4688 | D111: 107.65991 | E111: 103.62038 | F111: 101.68444 | G111: 25.201458 | H111: 100.14429 | I111: 107.31217 | J111: 103.28569 | K111: 101.356 | L111: 31.487475
B112: 2016 | C112: 101.20349 | D112: 107.64316 | E112: 106.52541 | F112: 103.15944 | G112: 25.197538 | H112: 100.87723 | I112: 107.29614 | J112: 106.182 | K112: 102.82688 | L112: 31.482774
B113: 2017 | C113: 101.653 | D113: 108.05918 | E113: 108.13243 | F113: 105.69528 | G113: 25.294921 | H113: 101.32238 | I113: 107.70772 | J113: 107.78073 | K113: 105.35151 | L113: 31.603538
B114: 2018 | C114: 102.34357 | D114: 109.62905 | E114: 109.81987 | F114: 106.8042 | G114: 25.662403 | H114: 101.97954 | I114: 109.2391 | J114: 109.42924 | K114: 106.4243 | L114: 32.052875
B115: 2019 | C115: 103.19203 | D115: 111.75276 | E115: 110.56669 | F115: 107.6639 | G115: 26.159529 | H115: 102.72059 | I115: 111.2422 | J115: 110.06155 | K115: 107.17203 | L115: 32.640623
... B127: 2031 | C127: 105.0503 | D127: 114.58088 | E127: 115.13368 | F127: 117.5073 | G127: 26.821547 | H127: 101.00357 | I127: 110.16701 | J127: 110.69851 | K127: 112.98069 | L127: 32.325141
C128: Index: 2008/2009 =100 | H128: Index: 2008/2009 =100
B129: 2008-09 | C129: 100 | D129: 100 | E129: 100 | F129: 100 | G129: 23.372277 | H129: 100 | I129: 100 | J129: 100 | K129: 100 | L129: 29.288286
B130: 2009-10 | C130: 97.646337 | D130: 101.5824 | E130: 97.823013 | F130: 96.46427 | G130: 23.74212 | H130: 97.562218 | I130: 101.49489 | J130: 97.738742 | K130: 96.38117 | L130: 29.726115
B131: 2010-11 | C131: 97.749046 | D131: 100.10333 | E131: 99.852334 | F131: 98.072686 | G131: 23.396427 | H131: 97.582431 | I131: 99.932701 | J131: 99.682134 | K131: 97.905519 | L131: 29.268575
B132: 2011-12 | C132: 97.171986 | D132: 98.518021 | E132: 98.043925 | F132: 97.957043 | G132: 23.025905 | H132: 96.952145 | I132: 98.295135 | J132: 97.822112 | K132: 97.735426 | L132: 28.78896
B133: 2012-13 | C133: 97.962895 | D133: 99.499075 | E133: 100.06953 | F133: 98.777107 | G133: 23.255199 | H133: 97.730593 | I133: 99.26313 | J133: 99.832233 | K133: 98.542874 | L133: 29.072469
B134: 2013-14 | C134: 98.742494 | D134: 101.76004 | E134: 101.35744 | F134: 100.22156 | G134: 23.783638 | H134: 98.481942 | I134: 101.49153 | J134: 101.08999 | K134: 99.957103 | L134: 29.725129
B135: 2014-15 | C135: 100.28142 | D135: 103.21772 | E135: 103.78444 | F135: 102.58234 | G135: 24.124332 | H135: 99.994255 | I135: 102.92215 | J135: 103.48724 | K135: 102.28858 | L135: 30.144133
...

Sheet 1.6
A1: Back to contents
B2: 1.6 Labour market
C3: Employment (16+, millions) | D3: Employment rate (16+, per cent) | E3: Employees (16+, millions) | F3: ILO unemployment (16+, millions) | G3: ILO unemployment rate (16+, per cent) | H3: Participation rate (16+, per cent) | I3: Average hours worked | J3: Total hours worked (millions) | K3: Labour income share (per cent) | L3: Labour compensation share (per cent) | M3: Compensation of employees (£ billion) (a) | N3: Wages and salaries (£ billion) (a-b) | O3: Employers social contributions (£ billion) (b) | P3: Mixed income (£ billion) | Q3: Average weekly earnings growth (per cent) | R3: Average weekly earnings index (2008Q1=100) | S3: Average hourly earnings index (2008Q1=100) | T3: Productivity per hour index (2008Q1 =100) | U3: Productivity per worker index (2008Q1 =100) | V3: Real product wage (2008Q1 =100) | W3: Real consumption wage (2008Q1 =100) | X3: Real weekly earnings index (2008Q1=100) | Y3: Real hourly earnings index (2008Q1=100)
B4: 2008Q1 | C4: 29.684 | D4: 60.337012 | E4: 25.806 | F4: 1.622 | G4: 5.1811154 | H4: 63.633961 | I4: 32.2 | J4: 955.8248 | K4: 47.970559 | L4: 56.230424 | M4: 202.225 | N4: 169.209 | O4: 33.016 | P4: 22.537 | Q4: 2.5663719 | R4: 100 | S4: 100 | T4: 100 | U4: 100 | V4: 100 | W4: 100 | X4: 100 | Y4: 100
B5: 2008Q2 | C5: 29.722 | D5: 60.269695 | E5: 25.863 | F5: 1.68 | G5: 5.3499777 | H5: 63.676366 | I5: 31.8 | J5: 945.1596 | K5: 47.389412 | L5: 55.448276 | M5: 200.18 | N5: 167.728 | O5: 32.452 | P5: 23.103 | Q5: 2.5181341 | R5: 98.906288 | S5: 100.15039 | T5: 100.58561 | U5: 99.336095 | V5: 97.770016 | W5: 97.260852 | X5: 96.950314 | Y5: 98.169814
B6: 2008Q3 | C6: 29.58 | D6: 59.855521 | E6: 25.762 | F6: 1.84 | G6: 5.8561426 | H6: 63.578786 | I6: 32 | J6: 946.56 | K6: 47.173476 | L6: 55.173734 | M6: 199.128 | N6: 166.956 | O6: 32.172 | P6: 22.746 | Q6: 0.3669952 | R6: 98.837031 | S6: 99.454762 | T6: 98.787921 | U6: 98.174331 | V6: 95.56305 | W6: 95.81597 | X6: 95.687985 | Y6: 96.286035
B7: 2008Q4 | C7: 29.528 | D7: 59.632046 | E7: 25.7 | F7: 2.003 | G7: 6.3524785 | H7: 63.677121 | I7: 31.9 | J7: 941.9432 | K7: 47.439505 | L7: 55.674832 | M7: 198.142 | N7: 165.392 | O7: 32.75 | P7: 23.264 | Q7: -0.37208675 | R7: 98.147357 | S7: 99.070373 | T7: 97.17152 | U7: 96.266195 | V7: 93.987986 | W7: 96.130699 | X7: 94.903576 | Y7: 95.796086
B8: 2009Q1 | C8: 29.366 | D8: 59.187746 | E8: 25.522 | F8: 2.235 | G8: 7.072561 | H8: 63.692432 | I8: 31.5 | J8: 925.029 | K8: 47.721378 | L8: 56.205247 | M8: 195.359 | N8: 162.291 | O8: 33.068 | P8: 23.715 | Q8: -3.0211642 | R8: 96.978836 | S8: 99.133921 | T8: 96.946676 | U8: 94.83914 | V8: 92.92483 | W8: 95.216917 | X8: 94.149135 | Y8: 96.241338
B9: 2009Q2 | C9: 29.087 | D9: 58.511024 | E9: 25.244 | F9: 2.448 | G9: 7.7628032 | H9: 63.435388 | I9: 31.7 | J9: 922.0579 | K9: 48.522039 | L9: 57.008719 | M9: 198.045 | N9: 165.019 | O9: 33.026 | P9: 23.805 | Q9: 0.79734916 | R9: 99.694916 | S9: 101.26739 | T9: 96.977773 | U9: 95.471907 | V9: 95.239864 | W9: 97.4464 | X9: 95.723943 | Y9: 97.233784
B10: 2009Q3 | C10: 29.069 | D10: 58.348053 | E10: 25.188 | F10: 2.475 | G10: 7.8461831 | H10: 63.315937 | I10: 31.5 | J10: 915.6735 | K10: 48.096396 | L10: 56.369335 | M10: 197.252 | N10: 164.89 | O10: 32.362 | P10: 23.253 | Q10: 1.0132113 | R10: 99.838459 | S10: 102.05709 | T10: 97.775101 | U10: 95.649555 | V10: 95.069408 | W10: 97.178584 | X10: 95.238711 | Y10: 97.355126
B11: 2009Q4 | C11: 29.102 | D11: 58.283265 | E11: 25.19 | F11: 2.453 | G11: 7.7737284 | H11: 63.195946 | I11: 31.5 | J11: 916.713 | K11: 48.434883 | L11: 57.398407 | M11: 199.924 | N11: 165.029 | O11: 34.895 | P11: 23.528 | Q11: 1.8006908 | R11: 99.914688 | S11: 102.13501 | T11: 97.989812 | U11: 95.859599 | V11: 97.433682 | W11: 99.025026 | X11: 94.622408 | Y11: 96.725128
B12: 2010Q1 | C12: 29.013 | D12: 57.97614 | E12: 25.059 | F12: 2.526 | G12: 8.0091315 | H12: 63.0238 | I12: 31.6 | J12: 916.8108 | K12: 47.404088 | L12: 56.58485 | M12: 201.034 | N12: 164.483 | O12: 36.551 | P12: 24.245 | Q12: 3.2232551 | R12: 100.10471 | S12: 102.00543 | T12: 98.802115 | U12: 96.961082 | V12: 97.935847 | W12: 100.03002 | X12: 94.102385 | Y12: 95.889139
B13: 2010Q2 | C13: 29.192 | D13: 58.203569 | E13: 25.243 | F13: 2.488 | G13: 7.8535353 | H13: 63.164191 | I13: 31.6 | J13: 922.4672 | K13: 47.059466 | L13: 56.250481 | M13: 201.716 | N13: 164.682 | O13: 37.034 | P13: 24.938 | Q13: -0.2002655 | R13: 99.495262 | S13: 101.38441 | T13: 99.317937 | U13: 97.467293 | V13: 97.5518 | W13: 98.908182 | X13: 92.340336 | Y13: 94.093634
B14: 2010Q3 | C14: 29.385 | D14: 58.456672 | E14: 25.339 | F14: 2.47 | G14: 7.7538848 | H14: 63.370335 | I14: 31.6 | J14: 928.566 | K14: 47.061503 | L14: 56.163446 | M14: 203.533 | N14: 166.563 | O14: 36.97 | P14: 24.59 | Q14: 0.41265018 | R14: 100.25044 | S14: 102.15393 | T14: 99.245662 | U14: 97.396364 | V14: 97.647891 | W14: 98.732456 | X14: 92.769528 | Y14: 94.530975
B15: 2010Q4 | C15: 29.324 | D15: 58.202171 | E15: 25.315 | F15: 2.503 | G15: 7.8643919 | H15: 63.170117 | I15: 31.8 | J15: 932.5032 | K15: 47.04221 | L15: 56.036114 | M15: 203.636 | N15: 166.887 | O15: 36.749 | P15: 25.327 | Q15: 0.62652507 | R15: 100.54068 | S15: 101.80534 | T15: 98.876596 | U15: 97.648315 | V15: 97.248156 | W15: 97.892329 | X15: 92.105518 | Y15: 93.264078
... B100: 2032Q1 | C100: 35.496917 | D100: 60.601175 | E100: 30.607421 | F100: 1.5330402 | G100: 4.14 | H100: 63.218417 | I100: 31.674836 | J100: 1124.359 | K100: 45.116519 | L100: 54.554351 | M100: 467.92386 | N100: 377.11308 | O100: 90.810777 | P100: 56.99786 | Q100: 2.5624905 | R100: 187.90663 | S100: 191.02209 | T100: 112.64432 | U100: 110.80715 | V100: 108.18038 | W100: 109.27756 | X100: 96.525121 | Y100: 98.125494
B101: 2008 | C101: 29.6285 | D101: 60.023569 | E101: 25.78275 | F101: 1.78625 | G101: 5.6849286 | H101: 63.641559 | I101: 31.975 | J101: 947.3719 | K101: 47.492631 | L101: 55.630729 | M101: 799.675 | N101: 669.285 | O101: 130.39 | P101: 91.65 | Q101: 1.2583379 | R101: 100 | S101: 100 | T101: 100 | U101: 100 | V101: 100 | W101: 100 | X101: 100 | Y101: 100
B102: 2009 | C102: 29.156 | D102: 58.582522 | E102: 25.286 | F102: 2.40275 | G102: 7.6138189 | H102: 63.409926 | I102: 31.55 | J102: 919.86835 | K102: 48.193381 | L102: 56.744784 | M102: 790.58 | N102: 657.229 | O102: 133.351 | P102: 94.301 | Q102: 0.12781303 | R102: 100.12781 | S102: 101.4766 | T102: 98.271146 | U102: 96.958841 | V102: 98.282234 | W102: 99.91249 | X102: 98.005676 | Y102: 99.325879
B103: 2010 | C103: 29.2285 | D103: 58.209638 | E103: 25.239 | F103: 2.49675 | G103: 7.8702359 | H103: 63.182111 | I103: 31.65 | J103: 925.0868 | K103: 47.140526 | L103: 56.256781 | M103: 809.919 | N103: 662.615 | O103: 147.304 | P103: 99.1 | Q103: 1.0072471 | R103: 101.13635 | S103: 102.17487 | T103: 99.923657 | U103: 98.9047 | V103: 100.79072 | W103: 101.63292 | X103: 95.832127 | Y103: 96.816186
B104: 2011 | C104: 29.381 | D104: 58.008367 | E104: 25.3235 | F104: 2.593 | G104: 8.1095071 | H104: 63.12749 | I104: 31.575 | J104: 927.6992 | K104: 46.581295 | L104: 55.488893 | M104: 826.366 | N104: 677.614 | O104: 148.752 | P104: 100.268 | Q104: 1.9223717 | R104: 103.08056 | S104: 104.38641 | T104: 100.49275 | U104: 99.229084 | V104: 100.91352 | W104: 99.469423 | X104: 93.500789 | Y104: 94.68528
B105: 2012 | C105: 29.723 | D105: 58.27711 | E105: 25.4985 | F105: 2.56975 | G105: 7.958284 | H105: 63.315747 | I105: 31.825 | J105: 945.95045 | K105: 45.874968 | L105: 54.878237 | M105: 841.692 | N105: 686.682 | O105: 155.01 | P105: 103.151 | Q105: 0.64272569 | R105: 103.74309 | S105: 104.23206 | T105: 100.06254 | U105: 99.58636 | V105: 100.63054 | W105: 98.971603 | X105: 91.513518 | Y105: 91.944847
B106: 2013 | C106: 30.09675 | D106: 58.592287 | E106: 25.8345 | F106: 2.474 | G106: 7.5965131 | H106: 63.408987 | I106: 32.05 | J106: 964.60415 | K106: 46.208649 | L106: 54.914727 | M106: 873.956 | N106: 718.198 | O106: 155.758 | P106: 108.508 | Q106: 3.229328 | R106: 107.09329 | S106: 106.84269 | T106: 99.809087 | U106: 100.03978 | V106: 101.06831 | W106: 99.221517 | X106: 92.106445 | Y106: 91.890907
B107: 2014 | C107: 30.81825 | D107: 59.543186 | E107: 26.2605 | F107: 2.02625 | G107: 6.1695433 | H107: 63.458608 | I107: 32.175 | J107: 991.58278 | K107: 45.925317 | L107: 53.983966 | M107: 896.603 | N107: 745.498 | O107: 151.105 | P107: 115.632 | Q107: 2.1173089 | R107: 109.36079 | S107: 108.681 | T107: 100.16047 | U107: 100.78512 | V107: 100.52331 | W107: 98.972477 | X107: 92.702215 | Y107: 92.125977
B108: 2015 | C108: 31.34575 | D108: 60.109137 | E108: 26.771 | F108: 1.7805 | G108: 5.3755561 | H108: 63.523722 | I108: 32.1 | J108: 1006.209 | K108: 46.290539 | L108: 54.402557 | M108: 926.308 | N108: 769.907 | O108: 156.401 | P108: 122.582 | Q108: 1.304837 | R108: 110.78777 | S108: 110.35635 | T108: 100.82232 | U108: 101.20997 | V108: 100.93797 | W108: 100.62943 | X108: 93.874184 | Y108: 93.508631
B109: 2016 | C109: 31.81025 | D109: 60.549274 | E109: 27.038 | F109: 1.63475 | G109: 4.8881177 | H109: 63.661086 | I109: 32.05 | J109: 1019.5168 | K109: 46.07361 | L109: 54.382406 | M109: 963.779 | N109: 797.208 | O109: 166.571 | P109: 126.455 | Q109: 2.5234968 | R109: 113.5835 | S109: 113.3177 | T109: 101.69742 | U109: 101.93269 | V109: 102.45778 | W109: 102.39133 | X109: 95.612374 | Y109: 95.388632
B110: 2017 | C110: 32.12775 | D110: 60.816565 | E110: 27.33 | F110: 1.47925 | G110: 4.4016679 | H110: 63.616811 | I110: 32.1 | J110: 1031.2937 | K110: 46.110045 | L110: 54.335116 | M110: 1001.409 | N110: 828.911 | O110: 172.498 | P110: 138.119 | Q110: 2.8658423 | R110: 116.83862 | S110: 116.38364 | T110: 103.57985 | U110: 103.97654 | V110: 103.70142 | W110: 103.4296 | X110: 95.782503 | Y110: 95.409519
B111: 2018 | C111: 32.50675 | D111: 61.210944 | E111: 27.72625 | F111: 1.385 | G111: 4.0866365 | H111: 63.818989 | I111: 32 | J111: 1040.2193 | K111: 46.317922 | L111: 54.592898 | M111: 1042.411 | N111: 862.715 | O111: 179.696 | P111: 143.106 | Q111: 2.5906882 | R111: 119.86554 | S111: 119.7719 | T111: 104.28259 | U111: 104.35848 | V111: 104.21243 | W111: 104.01652 | X111: 95.887776 | Y111: 95.812864
B112: 2019 | C112: 32.923 | D112: 61.655758 | E112: 27.9615 | F112: 1.311 | G112: 3.8295746 | H112: 64.110922 | I112: 32.066248 | J112: 1055.7 | K112: 46.45491 | L112: 55.122437 | M112: 1091.121 | N112: 895.845 | O112: 195.276 | P112: 150.766 | Q112: 2.9665578 | R112: 123.42142 | S112: 123.07021 | T112: 104.0446 | U112: 104.33354 | V112: 105.50453 | W112: 106.44828 | X112: 96.99514 | Y112: 96.719129
... B124: 2031 | C124: 35.388344 | D124: 60.625273 | E124: 30.543582 | F124: 1.5307532 | G124: 4.146248 | H124: 63.247679 | I124: 31.695053 | J124: 1121.635 | K124: 45.202141 | L124: 54.656403 | M124: 1838.2228 | N124: 1481.7872 | O124: 356.43563 | P124: 222.38105 | Q124: 2.6014041 | R124: 186.88912 | S124: 188.53982 | T124: 112.85036 | U124: 111.85812 | V124: 111.2249 | W124: 111.90463 | X124: 98.939975 | Y124: 99.813864
B125: 2008-09 | C125: 29.549 | D125: 59.736252 | E125: 25.71175 | F125: 1.9395 | G125: 6.1577899 | H125: 63.656176 | I125: 31.8 | J125: 939.67295 | K125: 47.428649 | L125: 55.620822 | M125: 792.809 | N125: 662.367 | O125: 130.442 | P125: 92.828 | Q125: -0.15306947 | R125: 100 | S125: 100 | T125: 100 | U125: 100 | V125: 100 | W125: 100 | X125: 100 | Y125: 100
B126: 2009-10 | C126: 29.06775 | D126: 58.279621 | E126: 25.17025 | F126: 2.4755 | G126: 7.8479616 | H126: 63.242768 | I126: 31.575 | J126: 917.8138 | K126: 48.110293 | L126: 56.838309 | M126: 796.255 | N126: 659.421 | O126: 136.834 | P126: 94.831 | Q126: 1.6970123 | R126: 101.69701 | S126: 99.446784 | T126: 99.505219 | U126: 98.789441 | V126: 101.42879 | W126: 102.40765 | X126: 99.470127 | Y126: 97.269172
B127: 2010-11 | C127: 29.3355 | D127: 58.291221 | E127: 25.33875 | F127: 2.486 | G127: 7.8124148 | H127: 63.23106 | I127: 31.675 | J127: 929.20403 | K127: 47.062967 | L127: 56.108122 | M127: 817.066 | N127: 669.247 | O127: 147.819 | P127: 99.872 | Q127: 0.81519673 | R127: 102.52604 | S127: 100.79425 | T127: 100.73821 | U127: 100.33109 | V127: 102.65957 | W127: 102.3162 | X127: 96.87934 | Y127: 95.242924
B128: 2011-12 | C128: 29.38825 | D128: 57.914891 | E128: 25.28 | F128: 2.6305 | G128: 8.2154767 | H128: 63.098641 | I128: 31.575 | J128: 927.92903 | K128: 46.299187 | L128: 55.227052 | M128: 827.149 | N128: 677.154 | O128: 149.995 | P128: 100.708 | Q128: 1.41662 | R128: 103.97845 | S128: 101.00828 | T128: 101.53777 | U128: 100.8079 | V128: 102.85347 | W128: 100.42783 | X128: 94.200613 | Y128: 91.509749
B129: 2012-13 | C129: 29.8265 | D129: 58.379644 | E129: 25.60225 | F129: 2.5465 | G129: 7.8662785 | H129: 63.364002 | I129: 31.9 | J129: 951.4727 | K129: 45.724235 | L129: 54.680009 | M129: 845.182 | N129: 689.791 | O129: 155.391 | P129: 103.567 | Q129: 0.58402511 | R129: 104.58571 | S129: 100.54703 | T129: 100.52615 | U129: 100.83114 | V129: 101.99388 | W129: 99.755971 | X129: 92.301257 | Y129: 88.736953
B130: 2013-14 | C130: 30.2745 | D130: 58.827899 | E130: 25.91375 | F130: 2.392 | G130: 7.3237031 | H130: 63.476467 | I130: 32.075 | J130: 971.05703 | K130: 46.550122 | L130: 55.136331 | M130: 885.826 | N130: 730.44 | O130: 155.386 | P130: 111.985 | Q130: 4.6200428 | R130: 109.41761 | S130: 103.65118 | T130: 100.63832 | U130: 101.4979 | V130: 103.65555 | W130: 101.11802 | X130: 94.39055 | Y130: 89.416063
B131: 2014-15 | C131: 30.974 | D131: 59.731553 | E131: 26.42975 | F131: 1.92975 | G131: 5.8654188 | H131: 63.453362 | I131: 32.175 | J131: 996.58235 | K131: 45.713433 | L131: 53.703445 | M131: 900.902 | N131: 749.699 | O131: 151.203 | P131: 115.382 | Q131: 0.63280848 | R131: 110.11002 | S131: 104.89953 | T131: 101.11242 | U131: 102.29446 | V131: 101.88479 | W131: 100.13908 | X131: 94.000156 | Y131: 89.551997
B132: 2015-16 | C132: 31.45025 | D132: 60.193707 | E132: 26.82825 | F132: 1.746 | G132: 5.2604193 | H132: 63.535735 | I132: 32.1 | J132: 1009.5635 | K132: 46.401966 | L132: 54.513179 | M132: 934.25 | N132: 776.678 | O132: 157.572 | P132: 124.747 | Q132: 2.0598164 | R132: 112.37808 | S132: 107.42124 | T132: 101.76016 | U132: 102.70691 | V132: 103.24211 | W132: 102.33138 | X132: 95.839255 | Y132: 91.611923
B133: 2016-17 | C133: 31.9055 | D133: 60.637467 | E133: 27.11225 | F133: 1.59525 | G133: 4.7619545 | H133: 63.669427 | I133: 32.075 | J133: 1023.3747 | K133: 45.917079 | L133: 54.290222 | M133: 973.756 | N133: 803.83 | O133: 169.926 | P133: 128.019 | Q133: 2.4117981 | R133: 115.08841 | S133: 110.65792 | T133: 102.80241 | U133: 103.68244 | V133: 104.62426 | W133: 103.97557 | X133: 97.07563 | Y133: 93.338562
B134: 2017-18 | C134: 32.226 | D134: 60.923749 | E134: 27.44 | F134: 1.45225 | G134: 4.3122568 | H134: 63.669312 | I134: 32.025 | J134: 1032.0266 | K134: 46.321296 | L134: 54.554889 | M134: 1013.306 | N134: 839.159 | O134: 174.147 | P134: 140.573 | Q134: 3.1481634 | R134: 118.71158 | S134: 114.12303 | T134: 104.92226 | U134: 105.64917 | V134: 106.05575 | W134: 104.99001 | X134: 97.380803 | Y134: 93.616745
B135: 2018-19 | C135: 32.59825 | D135: 61.295413 | E135: 27.77825 | F135: 1.3555 | G135: 3.9924289 | H135: 63.844286 | I135: 32.10332 | J135: 1046.5246 | K135: 46.29982 | L135: 54.633123 | M135: 1051.824 | N135: 869.293 | O135: 182.531 | P135: 144.849 | Q135: 2.3295703 | R135: 121.47705 | S135: 116.50017 | T135: 104.76613 | U135: 105.75148 | V135: 106.34942 | W135: 105.71707 | X135: 97.439826 | Y135: 93.447744
...

Sheet 1.7
A1: Back to contents
B2: 1.7 Inflation
C3: Year-on-year growth | M3: Jan 1987=100 | N3: Jan 1987=100 | O3: 2015=100 | P3: 2015=100 | Q3: 2015=100 | R3: Jan 1987=100 | S3: 2015 = 100 | T3: 2016 = 100 | U3: 2023=100 | V3: 2023=100
C4: RPI | D4: RPIX | E4: CPI | F4: CPIH | G4: OOH | H4: Mortgage interest payments | I4: Actual rents for housing | J4: Private rentals for housing | K4: Consumer expenditure deflator | L4: GDP deflator | M4: RPI | N4: RPIX | O4: CPI | P4: CPIH | Q4: OOH | R4: Mortgage interest payments | S4: Actual rents for housing | T4: Private rentals for housing | U4: Consumer expenditure deflator | V4: GDP deflator
B5: 2008Q1 | C5: 3.9901478 | D5: 3.4989858 | E5: 2.3757202 | F5: 2.5889967 | G5: 2.7248973 | H5: 11.74954 | I5: 3.2925822 | J5: 2.2163408 | K5: 3.7081837 | L5: 2.2522523 | M5: 211.1 | N5: 204.1 | O5: 82.924333 | P5: 84.533333 | Q5: 91.733333 | R5: 404.53333 | S5: 83.364 | T5: 93.591667 | U5: 69.504492 | V5: 68.1
B6: 2008Q2 | C6: 4.3625788 | D6: 4.3833333 | E6: 3.4197229 | F6: 3.3613445 | G6: 2.7839644 | H6: 4.1721797 | I6: 3.4293759 | J6: 2.0361434 | K6: 3.8404405 | L6: 2.0710059 | M6: 215.3 | N6: 208.76667 | O6: 84.597333 | P6: 86.1 | Q6: 92.3 | R6: 393.66667 | S6: 84.729 | T6: 93.877333 | U6: 70.583377 | V6: 69
B7: 2008Q3 | C7: 4.9573477 | D7: 5.3473263 | E7: 4.8388413 | F7: 4.5218088 | G7: 2.6179941 | H7: -1.689441 | I7: 3.0344883 | J7: 2.1955058 | K7: 4.8777088 | L7: 4.0059347 | M7: 217.36667 | N7: 210.8 | O7: 85.653333 | P7: 87.066667 | Q7: 92.766667 | R7: 395.7 | S7: 85.044667 | T7: 94.383 | U7: 71.550648 | V7: 70.1
B8: 2008Q4 | C8: 2.7327612 | D8: 3.7860082 | E8: 3.8240517 | F8: 3.7257233 | G8: 2.5978778 | H8: -13.529838 | I8: 3.5605924 | J8: 1.766431 | K8: 3.8912418 | L8: 5.0445104 | M8: 215.53333 | N8: 210.16667 | O8: 85.758667 | P8: 87.233333 | Q8: 93.466667 | R8: 357.9 | S8: 85.898333 | T8: 94.617 | U8: 71.134459 | V8: 70.8
B9: 2009Q1 | C9: -0.078951682 | D9: 2.3844521 | E9: 3.0055512 | F9: 2.9574133 | G9: 2.2165698 | H9: -38.900791 | I9: 2.9169266 | J9: 0.6328911 | K9: 2.5865564 | L9: 3.9647577 | M9: 210.93333 | N9: 208.96667 | O9: 85.416667 | P9: 87.033333 | Q9: 93.766667 | R9: 247.16667 | S9: 85.795667 | T9: 94.184 | U9: 71.302265 | V9: 70.8
B10: 2009Q2 | C10: -1.2695462 | D10: 1.437011 | E10: 2.0887183 | F10: 2.013163 | G10: 1.5529072 | H10: -45.791702 | I10: 1.5846601 | J10: -0.30181229 | K10: 1.1663767 | L10: 2.7536232 | M10: 212.56667 | N10: 211.76667 | O10: 86.364333 | P10: 87.833333 | Q10: 93.733333 | R10: 213.4 | S10: 86.071667 | T10: 93.594 | U10: 71.406646 | V10: 70.9
B11: 2009Q3 | C11: -1.3801564 | D11: 1.3124605 | E11: 1.489726 | F11: 1.3016845 | G11: 0.64678405 | H11: -45.53955 | I11: 1.9170318 | J11: -1.2936652 | K11: -0.10533098 | L11: 1.5691869 | M11: 214.36667 | N11: 213.56667 | O11: 86.929333 | P11: 88.2 | Q11: 93.366667 | R11: 215.5 | S11: 86.675 | T11: 93.162 | U11: 71.475283 | V11: 71.2
B12: 2009Q4 | C12: 0.61862079 | D12: 2.7914354 | E12: 2.1031888 | F12: 1.6048911 | G12: -0.78459344 | H12: -39.051877 | I12: 0.9930344 | J12: -1.7445773 | K12: -0.066641541 | L12: -0.28248588 | M12: 216.86667 | N12: 216.03333 | O12: 87.562333 | P12: 88.633333 | Q12: 92.733333 | R12: 218.13333 | S12: 86.751333 | T12: 92.966333 | U12: 71.087054 | V12: 70.6
B13: 2010Q1 | C13: 3.9506956 | D13: 4.5461796 | E13: 3.2745366 | F13: 2.3362697 | G13: -1.6352648 | H13: -10.923803 | I13: 1.1329244 | J13: -1.2935672 | K13: -0.23669515 | L13: 1.1299435 | M13: 219.26667 | N13: 218.46667 | O13: 88.213667 | P13: 89.066667 | Q13: 92.233333 | R13: 220.16667 | S13: 86.767667 | T13: 92.965667 | U13: 71.133495 | V13: 71.6
B14: 2010Q2 | C14: 5.1434842 | D14: 5.1629152 | E14: 3.4566739 | F14: 2.5426946 | G14: -1.6002845 | H14: 4.6391753 | I14: 1.6443661 | J14: -0.55238584 | K14: 0.35228136 | L14: 1.1283498 | M14: 223.5 | N14: 222.7 | O14: 89.349667 | P14: 90.066667 | Q14: 92.233333 | R14: 223.3 | S14: 87.487 | T14: 93.077 | U14: 71.658198 | V14: 71.7
B15: 2010Q3 | C15: 4.7115534 | D15: 4.6823786 | E15: 3.0852647 | F15: 2.3431595 | G15: -0.92823991 | H15: 5.2436195 | I15: 1.1952697 | J15: 0.15671626 | K15: 0.95509884 | L15: 0.84269663 | M15: 224.46667 | N15: 223.56667 | O15: 89.611333 | P15: 90.266667 | Q15: 92.5 | R15: 226.8 | S15: 87.711 | T15: 93.308 | U15: 72.157943 | V15: 71.8
B16: 2010Q4 | C16: 4.6726097 | D16: 4.6597747 | E16: 3.3762615 | F16: 2.7453931 | G16: 0.071890726 | H16: 4.7677262 | I16: 1.517748 | J16: 0.94693778 | K16: 2.526509 | L16: 2.266289 | M16: 227 | N16: 226.1 | O16: 90.518667 | P16: 91.066667 | Q16: 92.8 | R16: 228.53333 | S16: 88.068 | T16: 93.846667 | U16: 72.883075 | V16: 72.2
... B92: 2029Q4 | C92: 3.0372 | D92: 2.9270383 | E92: 2.1300339 | F92: 2.2044852 | G92: 2.1867986 | H92: 5.4314418 | I92: 2.6517263 | J92: 2.1867986 | K92: 2.0964792 | L92: 1.933554 | M92: 466.27376 | N92: 455.71903 | O92: 155.01771 | P92: 154.87354 | Q92: 149.90629 | R92: 728.39513 | S92: 150.90414 | T92: 151.79367 | U92: 118.68725 | V92: 118.57285
B93: 2030Q1 | C93: 2.7928306 | E93: 2.1135571 | F93: 2.203348 | G93: 2.2522656 | H93: 5.5403475 | I93: 2.4591424 | J93: 2.2522656 | K93: 2.0641801 | L93: 1.9313442 | M93: 467.02175 | O93: 155.16135 | P93: 155.12199 | Q93: 150.68026 | S93: 151.41052 | T93: 152.5774 | U93: 119.27354 | V93: 119.15128
B94: 2030Q2 | C94: 2.3182819 | E94: 1.9971864 | F94: 2.1221404 | G94: 2.31 | I94: 2.5213494 | J94: 2.31 | K94: 2.0284806 | L94: 1.9463531 | M94: 471.86711 | O94: 156.92831 | P94: 156.73138 | Q94: 151.02582 | S94: 152.2823 | T94: 152.9273 | U94: 119.85793 | V94: 119.74046
B95: 2030Q3 | C95: 1.9371314 | E95: 1.9679683 | F95: 2.1117614 | G95: 2.38 | I95: 2.5696463 | J95: 2.38 | K95: 1.9989428 | L95: 1.9722726 | M95: 474.06776 | O95: 157.51219 | P95: 157.46233 | Q95: 152.19326 | S95: 153.7549 | T95: 154.10944 | U95: 120.44792 | V95: 120.33518
B96: 2030Q4 | C96: 2.1210072 | E96: 1.9635954 | F96: 2.1210072 | G96: 2.45 | I96: 2.6181198 | J96: 2.45 | K96: 1.9874005 | L96: 1.9847047 | M96: 476.16346 | O96: 158.06163 | P96: 158.15842 | Q96: 153.57899 | S96: 154.85499 | T96: 155.51262 | U96: 121.04604 | V96: 120.92617
B97: 2031Q1 | C97: 2.1625143 | E97: 2.0000638 | F97: 2.1625142 | G97: 2.52 | I97: 2.7063029 | J97: 2.52 | K97: 1.991092 | L97: 1.9803405 | M97: 477.12117 | O97: 158.26468 | P97: 158.47652 | Q97: 154.47741 | S97: 155.50815 | T97: 156.42235 | U97: 121.64839 | V97: 121.51088
B98: 2031Q2 | C98: 2.1716155 | E98: 1.999796 | F98: 2.1716156 | G98: 2.57 | I98: 2.7295145 | J98: 2.57 | K98: 1.9983476 | L98: 1.9623428 | M98: 482.11424 | O98: 160.06656 | P98: 160.13498 | Q98: 154.90718 | S98: 156.43887 | T98: 156.85753 | U98: 122.25311 | V98: 122.09018
B99: 2031Q3 | C99: 2.1806016 | E99: 1.9996873 | F99: 2.1806015 | G99: 2.62 | I99: 2.7640021 | J99: 2.62 | K99: 2.0022023 | L99: 1.9262406 | M99: 484.40529 | O99: 160.66194 | P99: 160.89596 | Q99: 156.18072 | S99: 158.00469 | T99: 158.14711 | U99: 122.85953 | V99: 122.65313
B100: 2031Q4 | C100: 2.1901945 | E100: 2.0003474 | F100: 2.1901945 | G100: 2.67 | I100: 2.7986178 | J100: 2.67 | K100: 2.0022059 | L100: 1.8912421 | M100: 486.59237 | O100: 161.22341 | P100: 161.6224 | Q100: 157.67955 | S100: 159.18879 | T100: 159.66481 | U100: 123.46963 | V100: 123.21317
B101: 2032Q1 | C101: 2.1989098 | E101: 1.9998958 | F101: 2.1989099 | G101: 2.72 | I101: 2.8133413 | J101: 2.72 | K101: 2.0022608 | L101: 1.8585415 | M101: 487.61263 | O101: 161.42981 | P101: 161.96128 | Q101: 158.67919 | S101: 159.88312 | T101: 160.67703 | U101: 124.08411 | V101: 123.76921
B102: 2008 | C102: 4.0062939 | D102: 4.2552305 | E102: 3.617752 | F102: 3.5524867 | G102: 2.6807173 | H102: -0.28914734 | I102: 3.3295609 | J102: 2.0527899 | K102: 4.081087 | L102: 3.3457249 | M102: 214.825 | N102: 208.45833 | O102: 84.733417 | P102: 86.233333 | Q102: 92.566667 | R102: 387.95 | S102: 84.759 | T102: 94.11725 | U102: 70.693244 | V102: 69.5
B103: 2009 | C103: -0.53144024 | D103: 1.9788127 | E103: 2.1653205 | F103: 1.9617317 | G103: 0.90025207 | H103: -42.376595 | I103: 1.8457234 | J103: -0.68071121 | K103: 0.88348997 | L103: 1.9784173 | M103: 213.68333 | N103: 212.58333 | O103: 86.568167 | P103: 87.925 | Q103: 93.4 | R103: 223.55 | S103: 86.323417 | T103: 93.476583 | U103: 71.317812 | V103: 70.875
B104: 2010 | C104: 4.6213244 | D104: 4.7628381 | E104: 3.2981716 | F104: 2.4926548 | G104: -1.0260528 | H104: 0.5144263 | I104: 1.3727446 | J104: -0.18961968 | K104: 0.89790462 | L104: 1.340388 | M104: 223.55833 | N104: 222.70833 | O104: 89.423333 | P104: 90.116667 | Q104: 92.441667 | R104: 224.7 | S104: 87.508417 | T104: 93.299333 | U104: 71.958178 | V104: 71.825
B105: 2011 | C105: 5.1999849 | D105: 5.2871843 | E105: 4.4636933 | F105: 3.8561124 | G105: 1.5144686 | H105: 3.0559265 | I105: 2.5092824 | J105: 1.2935962 | K105: 3.9007024 | L105: 2.5060912 | M105: 235.18333 | N105: 234.48333 | O105: 93.414917 | P105: 93.591667 | Q105: 93.841667 | R105: 231.56667 | S105: 89.70425 | T105: 94.50625 | U105: 74.765052 | V105: 73.625
B106: 2012 | C106: 3.2067183 | D106: 3.2162911 | E106: 2.8282421 | F106: 2.5732348 | G106: 1.6605985 | H106: 2.3499352 | I106: 3.3419078 | J106: 1.3813019 | K106: 1.6609013 | L106: 1.4940577 | M106: 242.725 | N106: 242.025 | O106: 96.056917 | P106: 96 | Q106: 95.4 | R106: 237.00833 | S106: 92.702083 | T106: 95.811667 | U106: 76.006826 | V106: 74.725
B107: 2013 | C107: 3.0418513 | D107: 3.0540922 | E107: 2.5647988 | F107: 2.2916667 | G107: 1.4063592 | H107: 2.7952605 | I107: 2.4712677 | J107: 1.2623724 | K107: 2.2151078 | L107: 2.1411843 | M107: 250.10833 | N107: 249.41667 | O107: 98.520583 | P107: 98.2 | Q107: 96.741667 | R107: 243.63333 | S107: 94.993 | T107: 97.021167 | U107: 77.690459 | V107: 76.325
B108: 2014 | C108: 2.3689734 | D108: 2.4423655 | E108: 1.4610314 | F108: 1.4511202 | G108: 1.4643811 | H108: -0.044465796 | I108: 2.3398215 | J108: 1.0477095 | K108: 1.1942222 | L108: 1.6049787 | M108: 256.03333 | N108: 255.50833 | O108: 99.96 | P108: 99.625 | Q108: 98.158333 | R108: 243.525 | S108: 97.215667 | T108: 98.037667 | U108: 78.618256 | V108: 77.55
B109: 2015 | C109: 0.97969011 | D109: 1.0273638 | E109: 0.040099373 | F109: 0.36804675 | G109: 1.8762204 | H109: -0.42432338 | I109: 2.8640788 | J109: 2.0016966 | K109: -0.33376507 | L109: 0.67698259 | M109: 258.54167 | N109: 258.13333 | O109: 100.00008 | P109: 99.991667 | Q109: 100 | R109: 242.49167 | S109: 100 | T109: 100.00008 | U109: 78.355855 | V109: 78.075
B110: 2016 | C110: 1.743755 | D110: 1.8724174 | E110: 0.65966612 | F110: 1.0084175 | G110: 2.35 | H110: -3.0928896 | I110: 1.7561667 | J110: 2.4230813 | K110: 1.2447631 | L110: 1.6970861 | M110: 263.05 | N110: 262.96667 | O110: 100.65975 | P110: 101 | Q110: 102.35 | R110: 234.99167 | S110: 101.75617 | T110: 102.42317 | U110: 79.3312 | V110: 79.4
B111: 2017 | C111: 3.5829689 | D111: 3.8059323 | E111: 2.6831314 | F111: 2.5577557 | G111: 1.9866471 | H111: -4.3760418 | I111: 0.95088422 | J111: 1.7266601 | K111: 1.7624913 | L111: 1.5743073 | M111: 272.475 | N111: 272.975 | O111: 103.36058 | P111: 103.58333 | Q111: 104.38333 | R111: 224.70833 | S111: 102.72375 | T111: 104.19167 | U111: 80.729406 | V111: 80.65
B112: 2018 | C112: 3.3428144 | D112: 3.3397442 | E112: 2.4780562 | F112: 2.2928399 | G112: 1.1416254 | H112: 3.5972557 | I112: 0.45348163 | J112: 0.99872031 | K112: 2.0277156 | L112: 1.9528828 | M112: 281.58333 | N112: 282.09167 | O112: 105.92192 | P112: 105.95833 | Q112: 105.575 | R112: 232.79167 | S112: 103.18958 | T112: 105.23225 | U112: 82.366368 | V112: 82.225
